Workbook

Sheet Tarifas 2026
C2: TARIFAS 2026 PRISA MEDIA
C4: AS COLOMBIA | D4: EP AMÉRICA | E4: CARACOL | F4: LA W | G4: TROPICANA | H4: BÉSAME | I4: RADIOACKTIVA | J4: LOS 40
C5: Valor CPM | D5: Valor CPM | E5: Valor CPM | F5: Valor CPM | G5: Valor CPM | H5: Valor CPM | I5: Valor CPM | J5: Valor CPM | K5: IPC | L5: Salario Mínimo | M5: Los 40
B6: FORMATOS | C6: TARIFAS BRUTAS - VER POLÍTICA COMERCIAL PARA APLICAR DESCUENTOS
A7: DISPLAY | B7: Tradicionales | C7: 31000 | D7: 31000 | E7: 31000 | F7: 27000 | G7: =25000+(25000*K7) -> 28500 | H7: =25000+(25000*K7) -> 28500 | I7: =25000+(25000*K7) -> 28500 | J7: =25000+(25000*K7) -> 28500 | K7: 0.14 | L7: 0.14 | M7: 0.14
B8: Video Pre roll | C8: 54000 | D8: 54000 | E8: 74000 | F8: 65000 | G8: 68500 | H8: 68500 | I8: 68500 | J8: 68500 | K8: DISPLAY
B9: Audio Pre Roll (Max 30") | C9: 49000 | D9: N/A | E9: 61500 | F9: 54000 | G9: =50000+(50000*K7) -> 57000 | H9: =50000+(50000*K7) -> 57000 | I9: =50000+(50000*K7) -> 57000 | J9: =50000+(50000*K7) -> 57000 | K9: AS | L9: EP | M9: CRC | N9: TROPICANA | O9: BÉSAME | P9: RADIOACKTIVA | Q9: LOS 40
B10: Audiencias Extendidas (Geolocalización) Targeting Display | C10: N/A | D10: N/A | E10: 22000 | G10: 22000 | H10: 22000 | I10: 22000 | J10: 22000 | K10: =100000*C7/1000 -> 3100000 | L10: =100000*D7/1000 -> 3100000 | M10: =100000*E7/1000 -> 3100000 | N10: =100000*G7/1000 -> 2850000 | O10: =100000*H7/1000 -> 2850000 | P10: =100000*I7/1000 -> 2850000 | Q10: =100000*J7/1000 -> 2850000
B11: Audiencias Extendidas (Geolocalización) Targeting Rich Media | C11: N/A | D11: N/A | E11: 31500 | G11: 31500 | H11: 31500 | I11: 31500 | J11: 31500
B12: Patrocinio Podcast (Spreaker) - Se compra por CPM Colombia | C12: N/A | D12: N/A | E12: 20100 | F12: 17600 | G12: 20100 | H12: 20100 | I12: 20100 | J12: 20100
C13: Desktop & Mobile - Formatos por impresiones - Formatos Geo y Spreaker no aplica descuento. | K13: VIDEO
K14: AS | L14: EP | M14: CRC | N14: TROPICANA | O14: BÉSAME | P14: RADIOACKTIVA | Q14: LOS 40
C15: TARIFAS BRUTAS - VER POLÍTICA COMERCIAL PARA APLICAR DESCUENTOS | K15: =100000*C8/1000 -> 5400000 | L15: =100000*D8/1000 -> 5400000 | M15: =100000*E8/1000 -> 7400000 | N15: =100000*G8/1000 -> 6850000 | O15: =100000*G8/1000 -> 6850000 | P15: =100000*H8/1000 -> 6850000 | Q15: =100000*I8/1000 -> 6850000
A16: PRES FIJA | B16: Brand Day (24 horas) | C16: 16000000 | D16: 10300000 | E16: 20500000 | F16: 18000000 | G16: 7400000 | H16: =5000000+(5000000*K7) -> 5700000 | I16: 8000000 | J16: =5000000+(5000000*K7) -> 5700000
B17: Brand Day Interactivo (24 horas) | C17: 18300000 | D17: 13700000 | E17: 25000000 | F17: 22000000 | G17: 9100000 | H17: 8000000 | I17: 9200000 | J17: 8000000
B18: Patrocinio Sección Interna (24 horas) | C18: 1700000 | D18: 2900000 | E18: 4000000 | F18: 4800000 | G18: 2900000 | H18: 2900000 | I18: 2900000 | J18: 2300000
B19: Botón Fijo (24 horas) | C19: 2300000 | D19: 1700000 | E19: 7000000 | F19: 6500000 | G19: 1700000 | H19: 3400000 | I19: 2900000 | J19: 2300000
C20: Desktop & Mobile - Formatos por 24 horas sujetos a disponibilidad
C22: TARIFAS NETAS (NO APLICA DESCUENTO)
A23: FORMATOS DE VIDEO A LA MEDIDA | B23: Video Corto 3 talentos + Reel en IG y Tiktok - Incluye Producción - Video Corto* | C23: N/A | D23: N/A | E23: N/A | F23: 14000000 | G23: ='Video Corto'!K83 -> 15600000 | H23: ='Video Corto'!K119 -> 9850000 | I23: ='Video Corto'!K49 -> 15000000 | J23: ='Video Corto'!K6 -> 31500000 | K23: =6500000+(6500000*L23) -> 7410000 | L23: 0.14
B24: Video Corto 2 talentos + Reel en IG y Tiktok - Incluye Producción - Video Corto* | C24: N/A | D24: N/A | E24: N/A | F24: 14000000 | G24: ='Video Corto'!K76 -> 13600000 | H24: ='Video Corto'!K112 -> 9300000 | I24: ='Video Corto'!K42 -> 13200000 | J24: ='Video Corto'!K13 -> 27000000 | K24: =6500000+(6500000*L24) -> 7410000 | L24: 0.14
B25: Video Corto 1 talento comercial + Reel en IG y Tiktok - Incluye Producción - Video Corto* | C25: 13600000 | D25: N/A | E25: ='Video Corto'!K141 -> 16000000 | G25: ='Video Corto'!K69 -> 11700000 | H25: ='Video Corto'!K105 -> 8200000 | I25: ='Video Corto'!K35 -> 11300000 | J25: ='Video Corto'!K20 -> 22500000 | K25: =6500000+(6500000*L25) -> 7410000 | L25: 0.14
B26: Video Corto *Local* con 1 talento comercial local + Reel en IG y Tiktok *Local* - Incluye Producción - Video Corto* (No aplica para ciudades Principales) | C26: N/A | D26: N/A | E26: N/A | G26: 2500000 | H26: 2500000 | I26: 2500000 | J26: N/A
B27: Video Historias *Local* con 1 talento comercial local + Historia en IG *Local* - Incluye Producción - Video Corto* (No aplica para ciudades Principales) | C27: N/A | D27: N/A | E27: N/A | G27: 1000000 | H27: 1000000 | I27: 1000000 | J27: N/A
B28: Video Sección + Reel en IG y Tiktok + Sección en Radio - Incluye Producción - Programa* | C28: N/A | D28: N/A | E28: N/A | G28: ='Video Programa (Secciones)'!K93 -> 9500000 | H28: ='Video Programa (Secciones)'!K146 -> 6700000 | I28: ='Video Programa (Secciones)'!K42 -> 9400000 | J28: ='Video Programa (Secciones)'!K7 -> 17400000 | K28: =5000000+(5000000*L28) -> 5700000 | L28: 0.14
B29: Video Sección + Reel en IG y Tiktok + Sección en Radio - Incluye Producción con Product Placement - Programa* | C29: N/A | D29: N/A | E29: N/A | G29: ='Video Programa (Secciones)'!K102 -> 12000000 | H29: ='Video Programa (Secciones)'!K155 -> 8700000 | I29: ='Video Programa (Secciones)'!K51 -> 11700000 | J29: ='Video Programa (Secciones)'!K16 -> 20000000
B30: Video Sección + Reel en IG y Tiktok + Sección en Radio - Incluye Producción con Product Placement con interacción - Programa* | C30: N/A | D30: N/A | E30: N/A | G30: ='Video Programa (Secciones)'!K111 -> 14300000 | H30: ='Video Programa (Secciones)'!K164 -> 10700000 | I30: ='Video Programa (Secciones)'!K60 -> 14400000 | J30: ='Video Programa (Secciones)'!K25 -> 22300000
B31: Video Sección Local + Reel en IG y Tiktok Local + Sección en Radio local - Incluye Producción - Programa* | C31: N/A | D31: N/A | E31: N/A | G31: 1000000 | H31: 1000000 | I31: 1000000 | J31: N/A
B32: Video Sección Local + Reel en IG y Tiktok Local + Sección en Radio local - Incluye Producción con Product Placement con interacción - Programa* | C32: N/A | D32: N/A | E32: N/A | G32: 1300000 | H32: 1300000 | I32: 1300000 | J32: N/A
B33: Sección Prime (Video) En vivo (Mención + Banner y Full Screen) Youtube y Tiktok - Programa* | C33: N/A | D33: N/A | E33: N/A | G33: ='Seccion Prime - BM - Spot'!E7 -> 1380000 | H33: ='Seccion Prime - BM - Spot'!F7 -> 1220000 | I33: ='Seccion Prime - BM - Spot'!G7 -> 1440000 | J33: ='Seccion Prime - BM - Spot'!H7 -> 2980000
B34: Video Sección Noticiero 6am W + Reel en IG y Tiktok + Sección en Radio (momento) - Incluye Producción con Product Placement - Programa* | C34: N/A | D34: N/A | E34: ='Video Programa (Secciones)'!K200 -> 35000000 | G34: N/A | H34: N/A | I34: N/A | J34: N/A
B35: Video Sección El Pulso, Dos Puntos, Hora 20, La Polémica, AS Mundial + Reel en IG y Tiktok + Sección en Radio (momento) - Incluye Producción con Product Placement - Programa* | C35: N/A | D35: N/A | E35: ='Video Programa (Secciones)'!K210 -> 20000000 | G35: N/A | H35: N/A | I35: N/A | J35: N/A
B36: Video Sección Luciérnaga + Reel en IG y Tiktok + Sección en Radio (momento) - Incluye Producción con Product Placement - Programa* | C36: N/A | D36: N/A | E36: ='Video Programa (Secciones)'!K220 -> 28000000 | G36: N/A | H36: N/A | I36: N/A | J36: N/A
B37: Video Sección Fin de Semana / El VBar + Reel en IG y Tiktok + Sección en Radio (momento) - Incluye Producción con Product Placement - Programa* | C37: N/A | D37: N/A | E37: ='Video Programa (Secciones)'!K230 -> 16000000 | G37: N/A | H37: N/A | I37: N/A | J37: N/A
B38: Video Sección Morning Gol / AS Noticias / Milonga / El Vbar / Latido / As Noticias FDS + Reel en IG y Tiktok + Sección en Radio - Incluye Producción con Product Placement - Programa* | C38: ='Video Programa (Secciones)'!K244 -> 14200000 | D38: N/A | E38: N/A | G38: N/A | H38: N/A | I38: N/A | J38: N/A
B39: Video Sección Rock & gol del AS / Banqueados / Rock & Gol del AS Transmisión FDS + Reel en IG y Tiktok + Sección en Radio - Incluye Producción con Product Placement - Programa* | C39: ='Video Programa (Secciones)'!K253 -> 14400000 | D39: N/A | E39: N/A | G39: N/A | H39: N/A | I39: N/A | J39: N/A
B40: Video Sección La Jugaba Bacana + Reel en IG y Tiktok + Sección en Radio - Incluye Producción con Product Placement - Programa* | C40: ='Video Programa (Secciones)'!K262 -> 14300000 | D40: N/A | E40: N/A | G40: N/A | H40: N/A | I40: N/A | J40: N/A
B41: Video Sección MontoyAS / La Fuga + Reel en IG y Tiktok + Sección en Radio - Incluye Producción con Product Placement - Programa* | C41: ='Video Programa (Secciones)'!K272 -> 14500000 | D41: N/A | E41: N/A | G41: N/A | H41: N/A | I41: N/A | J41: N/A
B42: Video Cubrimiento (Max 10 minutos) + Reel en IG y Tiktok / Video Largo* | C42: N/A | D42: N/A | E42: 15200000 | F42: =10000000+6500000 -> 16500000 | G42: N/A | H42: N/A | I42: N/A | J42: N/A | K42: =7000000+(7000000*L42) -> 7980000 | L42: 0.14
B43: Video Cubrimiento Local (Max 10 minutos) + Reel en IG y Tiktok local / Video Largo* | C43: N/A | D43: N/A | E43: 3500000 | G43: 3000000 | H43: 3000000 | I43: N/A | J43: N/A
...

Sheet Métricas
C2: PROMEDIOS PRISA MEDIA 2026
C4: AS COLOMBIA | D4: EP AMÉRICA | E4: CARACOL | F4: TROPICANA | G4: BÉSAME | H4: RADIOACKTIVA | I4: LOS 40
B6: FORMATOS | C6: FORMATOS PROMEDIO POR SALIDA - OBJETIVO: CPM
A7: DISPLAY | B7: Tradicionales | C7: Se recomienda tener un mínimo de 100.000 impresiones en 7 días para campañas de poca duración. Importante revisar el inventario disponible en los diferentes formatos.
B8: Video Pre roll
B9: Audio Pre Roll (Max 30")
B10: Audiencias Extendidas (Geolocalización) | C10: El alcance se calcula con ejercicios a la medida del anunciante
C12: FORMATOS PROMEDIO POR SALIDA - OBJETIVO: CPM
A13: PRES FIJA | B13: Brand Day (24 horas) | C13: 300000 | D13: 150000 | E13: 350000 | F13: 150000 | G13: 100000 | H13: 200000 | I13: 50000
B14: Brand Day Interactivo (24 horas) | C14: 400000 | D14: N/A | E14: 400000 | F14: 200000 | G14: 120000 | H14: 250000 | I14: 60000
B15: Patrocinio Sección Interna (24 horas) | C15: 100000 | D15: 50000 | E15: 60000 | F15: 50000 | G15: 90000 | H15: 70000 | I15: 60000
B16: Botón Fijo (24 horas) | C16: 200000 | D16: 60000 | E16: 120000 | F16: 100000 | G16: 80000 | H16: 80000 | I16: 30000
C17: Los alcances pueden variar dependiendo de la creatividad, el mensaje y la temática de la campaña.
C19: FORMATOS PROMEDIO POR SALIDA - OBJETIVO: REPRODUCCIONES
B20: Latido - Incluye producción + amplificación con Reel en Tiktok e Instagram + 4 cuñas de Radio en AS Mundial *Video Largo* | C20: 15000 | D20: N/A | E20: N/A | F20: N/A | G20: N/A | H20: N/A | I20: N/A
B21: La Polémica - Incluye producción + amplificación con Reel en Tiktok e Instagram + 4 cuñas de Radio en Pulso del Fútbol *Programa* | C21: N/A | D21: N/A | E21: 40000 | F21: N/A | G21: N/A | H21: N/A | I21: N/A
B22: El BVar - Incluye producción + amplificación con Reel en Tiktok e Instagram + 4 cuñas de Radio en el Bvar (FDS) *Programa* | C22: N/A | D22: N/A | E22: 15000 | F22: N/A | G22: N/A | H22: N/A | I22: N/A
B23: El Pulso del Fútbol - Incluye producción + amplificación con Reel en Tiktok e Instagram + 4 cuñas de Radio en Pulso del Fútbol *Programa* | C23: N/A | D23: N/A | E23: 60000 | F23: N/A | G23: N/A | H23: N/A | I23: N/A
B24: AS Mundial - Incluye producción + amplificación con Reel en Tiktok e Instagram + 4 cuñas de Radio en AS Mundial *Programa* | C24: N/A | D24: N/A | E24: 25000 | F24: N/A | G24: N/A | H24: N/A | I24: N/A
A25: FORMATOS DE VIDEO DE PRISA MEDIA (FRANQUCIAS) | B25: Probando Probando - Incluye producción + amplificación con Reel en Tiktok e Instagram + 9 Promos Estándar en Radio (3 en Dos puntos, 3 en Luciérnada y 3 en A Vivir FDS) *Video Corto* | C25: N/A | D25: N/A | E25: 15000 | F25: N/A | G25: N/A | H25: N/A | I25: N/A
B26: Entendencia - Incluye producción + amplificación con Reel en Tiktok e Instagram + 9 Promos Estándar en Radio (3 en Dos puntos, 3 en Luciérnada y 3 en A Vivir FDS) *Video Corto* | C26: N/A | D26: N/A | E26: 11000 | F26: N/A | G26: N/A | H26: N/A | I26: N/A
B27: Tecnología - Incluye producción + amplificación con Reel en Tiktok e Instagram + 9 Promos Estándar en Radio (3 en Dos puntos, 3 en Luciérnada y 3 en A Vivir FDS) *Video Corto* | C27: N/A | D27: N/A | E27: 150000 | F27: N/A | G27: N/A | H27: N/A | I27: N/A
B28: Check in - Incluye producción + amplificación con Reel en Tiktok e Instagram + 9 Promos Estándar en Radio (3 en Dos puntos, 3 en Luciérnada y 3 en A Vivir FDS) *Video Corto* | C28: N/A | D28: N/A | E28: 15000 | F28: N/A | G28: N/A | H28: N/A | I28: N/A
B29: Plaza Alvira / Bogotá - Incluye producción amplificación con Reel en Tiktok e Instagram + 12 Promos Estándar en Radio (3 en Dos puntos, 3 en Luciérnada, 3 en A Vivir FDS y 3 en Noticiero Media día) (este formato debe ir siempre con Radio) *Video Corto* | C29: N/A | D29: N/A | E29: 315000 | F29: N/A | G29: N/A | H29: N/A | I29: N/A
B30: La Michelada - Incluye producción + amplificación con Reel en Tiktok e Instagram + 9 Promos Estándar en Radio (3 en Dos puntos, 3 en Luciérnada y 3 en A Vivir FDS) *Video Podcast* | C30: N/A | D30: N/A | E30: 18000000 | G30: N/A | H30: N/A | I30: N/A
B31: Rock and Gol - Incluye producción + amplificación con Reel en Tiktok e Instagram + 15 promos en radio de 20" en programación musical nacional *Programa* | C31: N/A | D31: N/A | E31: N/A | F31: N/A | G31: N/A | H31: 30000 | I31: N/A
B32: Milonga - Incluye producción + amplificación con Reel en Tiktok e Instagram + 4 cuñas de Radio en AS Mundial *Video Largo* | C32: 30000 | D32: N/A | E32: N/A | F32: N/A | G32: N/A | H32: N/A | I32: N/A
B33: MontoyAS - Incluye producción + amplificación con Reel en Tiktok e Instagram + 4 cuñas de Radio en AS Mundial *Video Largo* | C33: 40000 | D33: N/A | E33: N/A | F33: N/A | G33: N/A | H33: N/A | I33: N/A
B34: La Fuga - Incluye producción + amplificación con Reel en Tiktok e Instagram + 4 cuñas de Radio en AS Mundial *Video Largo* | C34: 3000 | D34: N/A | E34: N/A | F34: N/A | G34: N/A | H34: N/A | I34: N/A
B35: Latido - Incluye producción + amplificación con Reel en Tiktok e Instagram + 4 cuñas de Radio en AS Mundial *Video Largo* | C35: 15000 | D35: N/A | E35: N/A | F35: N/A | G35: N/A | H35: N/A | I35: N/A
B36: La Polémica - Incluye producción + amplificación con Reel en Tiktok e Instagram + 4 cuñas de Radio en Pulso del Fútbol *Programa* | C36: N/A | D36: N/A | E36: 40000 | F36: N/A | G36: N/A | H36: N/A | I36: N/A
B37: El BVar - Incluye producción + amplificación con Reel en Tiktok e Instagram + 4 cuñas de Radio en el Bvar (FDS) *Programa* | C37: N/A | D37: N/A | E37: 15000 | F37: N/A | G37: N/A | H37: N/A | I37: N/A
B38: El Pulso del Fútbol - Incluye producción + amplificación con Reel en Tiktok e Instagram + 4 cuñas de Radio en Pulso del Fútbol *Programa* | C38: N/A | D38: N/A | E38: 60000 | F38: N/A | G38: N/A | H38: N/A | I38: N/A
B39: AS Mundial - Incluye producción + amplificación con Reel en Tiktok e Instagram + 4 cuñas de Radio en AS Mundial *Programa* | C39: N/A | D39: N/A | E39: 25000 | F39: N/A | G39: N/A | H39: N/A | I39: N/A
B40: Caracol - Los Protagonistas / En Territorio / Geniales y Mayores/ Yo se quién sabe lo que ud no sabe... con vino / Incluye producción + amplificación con Reel en Tiktok e Instagram + 9 Promos Estándar en Radio (3 en Dos puntos, 3 en Luciérnada y 3 en A Vivir FDS) Video Largo* Tarifa Bogotá | C40: N/A | D40: N/A | E40: 30000 | F40: N/A | G40: N/A | H40: N/A | I40: N/A
B41: Caracol - Parodias la Luciérnaga / El Sermón de Fraile / El Radar de Villar / Se lo Explico con Datos / Doble Clic Incluye producción + amplificación con Reel en Tiktok e Instagram + 9 Promos Estándar en Radio (3 en Dos puntos, 3 en Luciérnada y 3 en A Vivir FDS) Video Corto* Tarifa Bogotá | C41: N/A | D41: N/A | E41: 20000 | F41: N/A | G41: N/A | H41: N/A | I41: N/A
B42: Los 40: Team Hater / Maldito Milenial / Suplentes del Gol / + de 40 - Incluye producción + amplificación con Reel en Tiktok e Instagram +15 promos en radio de 20" en programación musical nacional *Programa* | C42: N/A | D42: N/A | E42: N/A | F42: N/A | G42: N/A | H42: N/A | I42: 50000
B43: Bésame - Historia de Cachos - Incluye producción + amplificación con Reel en Tiktok e Instagram +15 promos en radio de 20" en programación musical nacional *Video Largo* | C43: N/A | D43: N/A | E43: N/A | F43: 0 | G43: 5000 | H43: N/A | I43: N/A
B44: Bésame - Mechismes - Incluye producción + amplificación con Reel en Tiktok e Instagram +15 promos en radio de 20" en programación musical nacional *Video Largo* | C44: N/A | D44: N/A | E44: N/A | F44: N/A | G44: 150000 | H44: N/A | I44: N/A
B45: Bésame - Cartas a mi ex / Conversemos con Sandro / Puebliando / Mujeres que Transforman / Incluye producción + amplificación con Reel en Tiktok e Instagram +15 promos en radio de 20" en programación musical nacional Video Largo* | C45: N/A | D45: N/A | E45: N/A | F45: N/A | G45: 10000 | H45: N/A | I45: N/A
...

Sheet Video Corto
A1: LOS 40 - VIDEO CORTO RRSS IMPRESENTABLES (3 TALENTOS)
A2: MARCA | B2: CIUDAD | C2: PRODUCTO | D2: VALORIZACION | E2: VALOR VEZ | F2: VECES DIA | G2: No DIAS | H2: TOTAL | I2: VALOR BTO | J2: DTO | K2: VALOR NETO | L2: 0.14
A3: LOS40 | B3: DIGITAL | C3: DIGITAL | D3: VIDEO (PRODUCCIÓN) | E3: =L3 -> 17100000 | F3: 1 | G3: 1 | H3: 1 | I3: =E3*F3 -> 17100000 | J3: 0 | K3: =I3-I3*J3 -> 17100000 | L3: =15000000+(15000000*L2) -> 17100000
A4: LOS40 | B4: DIGITAL | C4: DIGITAL | D4: REEL IG (PUBLICACIÓN) | E4: 9000000 | F4: 1 | G4: 1 | H4: 1 | I4: =E4*F4 -> 9000000 | J4: 0.4 | K4: =I4-I4*J4 -> 5400000 | L4: =7800000+(7800000*L2) -> 8892000
A5: LOS40 | B5: DIGITAL | C5: DIGITAL | D5: VIDEO TIK TOK (PUBLICACIÓN) | E5: 15100000 | F5: 1 | G5: 1 | H5: 1 | I5: =E5*F5 -> 15100000 | J5: 0.40397351 | K5: =I5-I5*J5 -> 9000000 | L5: =13200000+(13200000*L2) -> 15048000
I6: =SUM(I3:I5) -> 41200000 | K6: =SUM(K3:K5) -> 31500000
A8: LOS 40 - VIDEO CORTO RRSS 2 TALENTOS (ROBERTO CARDONA O PIPE FLOREZ)
A9: MARCA | B9: CIUDAD | C9: PRODUCTO | D9: VALORIZACION | E9: VALOR VEZ | F9: VECES DIA | G9: No DIAS | H9: TOTAL | I9: VALOR BTO | J9: DTO | K9: VALOR NETO | L9: 0.14
A10: LOS40 | B10: DIGITAL | C10: DIGITAL | D10: VIDEO (PRODUCCIÓN) | E10: =L10 -> 11400000 | F10: 1 | G10: 1 | H10: 1 | I10: =E10*F10 -> 11400000 | J10: 0 | K10: =I10-I10*J10 -> 11400000 | L10: =10000000+(10000000*L9) -> 11400000
A11: LOS40 | B11: DIGITAL | C11: DIGITAL | D11: REEL IG (PUBLICACIÓN) | E11: 9000000 | F11: 1 | G11: 1 | H11: 1 | I11: =E11*F11 -> 9000000 | J11: 0.35 | K11: =I11-I11*J11 -> 5850000 | L11: =7800000+(7800000*L9) -> 8892000
A12: LOS40 | B12: DIGITAL | C12: DIGITAL | D12: VIDEO TIK TOK (PUBLICACIÓN) | E12: 15100000 | F12: 1 | G12: 1 | H12: 1 | I12: =E12*F12 -> 15100000 | J12: 0.35430464 | K12: =I12-I12*J12 -> 9750000 | L12: =13200000+(13200000*L9) -> 15048000
I13: =SUM(I10:I12) -> 35500000 | K13: =SUM(K10:K12) -> 27000000
A15: LOS 40 - VIDEO CORTO RRSS 1 SOLO TALENTO (ROBERTO CARDONA O PIPE FLOREZ)
A16: MARCA | B16: CIUDAD | C16: PRODUCTO | D16: VALORIZACION | E16: VALOR VEZ | F16: VECES DIA | G16: No DIAS | H16: TOTAL | I16: VALOR BTO | J16: DTO | K16: VALOR NETO | L16: 0.14
A17: LOS40 | B17: DIGITAL | C17: DIGITAL | D17: VIDEO (PRODUCCIÓN) | E17: =L17 -> 5700000 | F17: 1 | G17: 1 | H17: 1 | I17: =E17*F17 -> 5700000 | J17: 0 | K17: =I17-I17*J17 -> 5700000 | L17: =5000000+(5000000*L16) -> 5700000
A18: LOS40 | B18: DIGITAL | C18: DIGITAL | D18: REEL IG (PUBLICACIÓN) | E18: 9000000 | F18: 1 | G18: 1 | H18: 1 | I18: =E18*F18 -> 9000000 | J18: 0.3 | K18: =I18-I18*J18 -> 6300000 | L18: =7800000+(7800000*L16) -> 8892000
A19: LOS40 | B19: DIGITAL | C19: DIGITAL | D19: VIDEO TIK TOK (PUBLICACIÓN) | E19: 15100000 | F19: 1 | G19: 1 | H19: 1 | I19: =E19*F19 -> 15100000 | J19: 0.30463576 | K19: =I19-I19*J19 -> 10500000 | L19: =13200000+(13200000*L16) -> 15048000
I20: =SUM(I17:I19) -> 29800000 | K20: =SUM(K17:K19) -> 22500000
A22: LOS 40 - VIDEO CORTO RRSS (Talento sujeto a disponibilidad - NO es Impresentable)
A23: EMISORA | B23: CIUDAD | C23: PRODUCTO | D23: VALORIZACION | E23: VALOR VEZ | F23: VECES DIA | G23: No DIAS | H23: TOTAL | I23: VALOR BTO | J23: DTO | K23: VALOR NETO | L23: 0.14
A24: LOS40 | B24: DIGITAL | C24: LOS40.COM.CO | D24: VIDEO (PRODUCCIÓN) | E24: =L24 -> 5700000 | F24: 1 | G24: 1 | H24: 1 | I24: =E24*F24 -> 5700000 | J24: 0 | K24: =I24-I24*J24 -> 5700000 | L24: =5000000+(5000000*L23) -> 5700000
A25: LOS40 | B25: DIGITAL | C25: LOS40.COM.CO | D25: REEL IG (PUBLICACIÓN) | E25: 9000000 | F25: 1 | G25: 1 | H25: 1 | I25: =E25*F25 -> 9000000 | J25: 0.55 | K25: =I25-I25*J25 -> 4050000 | L25: =7800000+(7800000*L23) -> 8892000
A26: LOS40 | B26: DIGITAL | C26: LOS40.COM.CO | D26: VIDEO TIK TOK (PUBLICACIÓN) | E26: 15100000 | F26: 1 | G26: 1 | H26: 1 | I26: =E26*F26 -> 15100000 | J26: 0.55298013 | K26: =I26-I26*J26 -> 6750000 | L26: =13200000+(13200000*L23) -> 15048000
I27: =SUM(I24:I26) -> 29800000 | K27: =SUM(K24:K26) -> 16500000
A30: RADIOACKTIVA - VIDEO CORTO RRSS - 1 TALENTO BOGOTÁ
A31: MARCA | B31: CIUDAD | C31: PRODUCTO | D31: VALORIZACION | E31: VALOR VEZ | F31: VECES DIA | G31: No DIAS | H31: TOTAL | I31: VALOR BTO | J31: DTO | K31: VALOR NETO | L31: 0.14
A32: RADIOACKTIVA | B32: DIGITAL | C32: DIGITAL | D32: VIDEO (PRODUCCIÓN) | E32: =L32 -> 5700000 | F32: 1 | G32: 1 | H32: 1 | I32: =E32*F32 -> 5700000 | J32: 0 | K32: =I32-I32*J32 -> 5700000 | L32: =5000000+(5000000*L31) -> 5700000
A33: RADIOACKTIVA | B33: DIGITAL | C33: DIGITAL | D33: REEL IG (PUBLICACIÓN) | E33: =L33 -> 2462400 | F33: 1 | G33: 1 | H33: 1 | I33: =E33*F33 -> 2462400 | J33: 0.4 | K33: =I33-I33*J33 -> 1477440 | L33: =2160000+(2160000*L31) -> 2462400
A34: RADIOACKTIVA | B34: DIGITAL | C34: DIGITAL | D34: VIDEO TIK TOK (PUBLICACIÓN) | E34: =L34 -> 6840000 | F34: 1 | G34: 1 | H34: 1 | I34: =E34*F34 -> 6840000 | J34: 0.39728655 | K34: =I34-I34*J34 -> 4122560 | L34: =6000000+(6000000*L31) -> 6840000
I35: =SUM(I32:I34) -> 15002400 | K35: =SUM(K32:K34) -> 11300000
A37: RADIOACKTIVA - VIDEO CORTO RRSS 2 TALENTOS BOGOTÁ
A38: MARCA | B38: CIUDAD | C38: PRODUCTO | D38: VALORIZACION | E38: VALOR VEZ | F38: VECES DIA | G38: No DIAS | H38: TOTAL | I38: VALOR BTO | J38: DTO | K38: VALOR NETO | L38: 0.14
A39: RADIOACKTIVA | B39: DIGITAL | C39: DIGITAL | D39: VIDEO (PRODUCCIÓN) | E39: =L39 -> 5700000 | F39: 1 | G39: 1 | H39: 1 | I39: =E39*F39 -> 5700000 | J39: 0 | K39: =I39-I39*J39 -> 5700000 | L39: =5000000+(5000000*L38) -> 5700000
A40: RADIOACKTIVA | B40: DIGITAL | C40: DIGITAL | D40: REEL IG (PUBLICACIÓN) | E40: =L40 -> 2462400 | F40: 1 | G40: 1 | H40: 1 | I40: =E40*F40 -> 2462400 | J40: 0.2 | K40: =I40-I40*J40 -> 1969920 | L40: =2160000+(2160000*L38) -> 2462400
A41: RADIOACKTIVA | B41: DIGITAL | C41: DIGITAL | D41: VIDEO TIK TOK (PUBLICACIÓN) | E41: =L41 -> 6840000 | F41: 1 | G41: 1 | H41: 1 | I41: =E41*F41 -> 6840000 | J41: 0.19150877 | K41: =I41-I41*J41 -> 5530080 | L41: =6000000+(6000000*L38) -> 6840000
I42: =SUM(I39:I41) -> 15002400 | K42: =SUM(K39:K41) -> 13200000
A44: RADIOACKTIVA - VIDEO CORTO RRSS 3 TALENTOS BOGOTÁ
A45: MARCA | B45: CIUDAD | C45: PRODUCTO | D45: VALORIZACION | E45: VALOR VEZ | F45: VECES DIA | G45: No DIAS | H45: TOTAL | I45: VALOR BTO | J45: DTO | K45: VALOR NETO | L45: 0.14
A46: RADIOACKTIVA | B46: DIGITAL | C46: DIGITAL | D46: VIDEO (PRODUCCIÓN) | E46: =L46 -> 5700000 | F46: 1 | G46: 1 | H46: 1 | I46: =E46*F46 -> 5700000 | J46: 0 | K46: =I46-I46*J46 -> 5700000 | L46: =5000000+(5000000*L45) -> 5700000
A47: RADIOACKTIVA | B47: DIGITAL | C47: DIGITAL | D47: REEL IG (PUBLICACIÓN) | E47: =L47 -> 2462400 | F47: 1 | G47: 1 | H47: 1 | I47: =E47*F47 -> 2462400 | J47: 0 | K47: =I47-I47*J47 -> 2462400 | L47: =2160000+(2160000*L45) -> 2462400
...

Sheet Video Programa (Secciones)
A1: LOS 40 - VIDEO SECCIONES - IMPRESENTABLES
A2: MARCA | B2: CIUDAD | C2: PRODUCTO | D2: VALORIZACION | E2: VALOR VEZ | F2: VECES DIA | G2: No DIAS | H2: TOTAL | I2: VALOR BTO | J2: DTO | K2: VALOR NETO | L2: 0.14 | M2: 0.1
A3: LOS40 | B3: NACIONAL | C3: IMPRESENTABLES | D3: SECCION ESPECIAL(RADIO) | E3: =M3 -> 6188600 | F3: 1 | G3: 1 | H3: =F3*G3 -> 1 | I3: =H3*E3 -> 6188600 | J3: 0.69549273 | K3: =I3-(I3*J3) -> 1884473.7 | M3: =5626000+(5626000*M2) -> 6188600
A4: LOS40 | B4: DIGITAL | C4: DIGITAL | D4: PRODUCCIÓN CAPSULA DE VIDEO | E4: =L4 -> 2280000 | F4: 1 | G4: 1 | H4: =F4*G4 -> 1 | I4: =H4*E4 -> 2280000 | J4: 0 | K4: =I4-(I4*J4) -> 2280000 | L4: =2000000+(2000000*L2) -> 2280000
A5: LOS40 | B5: DIGITAL | C5: DIGITAL | D5: REEL IG (PUBLICACIÓN) | E5: 9000000 | F5: 1 | G5: 1 | H5: =F5*G5 -> 1 | I5: =H5*E5 -> 9000000 | J5: 0.45 | K5: =I5-(I5*J5) -> 4950000 | L5: =7800000+(7800000*L2) -> 8892000
A6: LOS40 | B6: DIGITAL | C6: DIGITAL | D6: VIDEO TIK TOK (PUBLICACIÓN) | E6: 15100000 | F6: 1 | G6: 1 | H6: =F6*G6 -> 1 | I6: =H6*E6 -> 15100000 | J6: 0.45128965 | K6: =I6-(I6*J6) -> 8285526.3 | L6: =13200000+(13200000*L2) -> 15048000
I7: =SUM(I3:I6) -> 32568600 | K7: =SUM(K3:K6) -> 17400000
A9: LOS 40 - VIDEO SECCIONES CON PRODUCT PLACEMENT SIN INTERACCIÓN - (Cliente entrega el producto)
A10: MARCA | B10: CIUDAD | C10: PRODUCTO | D10: VALORIZACION | E10: VALOR VEZ | F10: VECES DIA | G10: No DIAS | H10: TOTAL | I10: VALOR BTO | J10: DTO | K10: VALOR NETO | L10: 0.14 | M10: 0.1
A11: LOS40 | B11: NACIONAL | C11: IMPRESENTABLES | D11: SECCION ESPECIAL(RADIO) | E11: =M11 -> 6188600 | F11: 1 | G11: 1 | H11: =F11*G11 -> 1 | I11: =H11*E11 -> 6188600 | J11: 0.70110577 | K11: =I11-(I11*J11) -> 1849736.8 | M11: =5626000+(5626000*M10) -> 6188600
A12: LOS40 | B12: DIGITAL | C12: DIGITAL | D12: PRODUCCIÓN CAPSULA DE VIDEO | E12: =L12 -> 2280000 | F12: 1 | G12: 1 | H12: =F12*G12 -> 1 | I12: =H12*E12 -> 2280000 | J12: 0 | K12: =I12-(I12*J12) -> 2280000 | L12: =2000000+(2000000*L10) -> 2280000
A13: LOS40 | B13: DIGITAL | C13: DIGITAL | D13: REEL IG (PUBLICACIÓN) | E13: 9000000 | F13: 1 | G13: 1 | H13: =F13*G13 -> 1 | I13: =H13*E13 -> 9000000 | J13: 0.45 | K13: =I13-(I13*J13) -> 4950000 | L13: =7800000+(7800000*L10) -> 8892000
A14: LOS40 | B14: DIGITAL | C14: DIGITAL | D14: VIDEO TIK TOK (PUBLICACIÓN) | E14: 15100000 | F14: 1 | G14: 1 | H14: =F14*G14 -> 1 | I14: =H14*E14 -> 15100000 | J14: 0.45582781 | K14: =I14-(I14*J14) -> 8217000 | L14: =13200000+(13200000*L10) -> 15048000
A15: LOS40 | B15: DIGITAL | C15: DIGITAL | D15: PRODUCT PLACEMENT SIN INTERACCIÓN | E15: =L15 -> 2736000 | F15: 1 | G15: 1 | H15: =F15*G15 -> 1 | I15: =H15*E15 -> 2736000 | J15: 0.01196522 | K15: =I15-(I15*J15) -> 2703263.2 | L15: =2400000+(2400000*L10) -> 2736000
I16: =SUM(I11:I15) -> 35304600 | K16: =SUM(K11:K15) -> 20000000
A18: LOS 40 - VIDEO SECCIONES CON PRODUCT PLACEMENT + INTERACCIÓN - (Cliente entrega el producto)
A19: MARCA | B19: CIUDAD | C19: PRODUCTO | D19: VALORIZACION | E19: VALOR VEZ | F19: VECES DIA | G19: No DIAS | H19: TOTAL | I19: VALOR BTO | J19: DTO | K19: VALOR NETO | L19: 0.14 | M19: 0.1
A20: LOS40 | B20: NACIONAL | C20: IMPRESENTABLES | D20: SECCION ESPECIAL(RADIO) | E20: =M20 -> 6188600 | F20: 1 | G20: 1 | H20: =F20*G20 -> 1 | I20: =H20*E20 -> 6188600 | J20: 0.69798741 | K20: =I20-(I20*J20) -> 1869035.1 | M20: =5626000+(5626000*M19) -> 6188600
A21: LOS40 | B21: DIGITAL | C21: DIGITAL | D21: PRODUCCIÓN CAPSULA DE VIDEO | E21: =L21 -> 2280000 | F21: 1 | G21: 1 | H21: =F21*G21 -> 1 | I21: =H21*E21 -> 2280000 | J21: 0 | K21: =I21-(I21*J21) -> 2280000 | L21: =2000000+(2000000*L19) -> 2280000
A22: LOS40 | B22: DIGITAL | C22: DIGITAL | D22: REEL IG (PUBLICACIÓN) | E22: 9000000 | F22: 1 | G22: 1 | H22: =F22*G22 -> 1 | I22: =H22*E22 -> 9000000 | J22: 0.45 | K22: =I22-(I22*J22) -> 4950000 | L22: =7800000+(7800000*L19) -> 8892000
A23: LOS40 | B23: DIGITAL | C23: DIGITAL | D23: VIDEO TIK TOK (PUBLICACIÓN) | E23: 15100000 | F23: 1 | G23: 1 | H23: =F23*G23 -> 1 | I23: =H23*E23 -> 15100000 | J23: 0.45582781 | K23: =I23-(I23*J23) -> 8217000 | L23: =13200000+(13200000*L19) -> 15048000
A24: LOS40 | B24: DIGITAL | C24: DIGITAL | D24: PRODUCT PLACEMENT + INTERACCIÓN | E24: =L24 -> 5016000 | F24: 1 | G24: 1 | H24: =F24*G24 -> 1 | I24: =H24*E24 -> 5016000 | J24: 0.0063865805 | K24: =I24-(I24*J24) -> 4983964.9 | L24: =4400000+(4400000*L19) -> 5016000
I25: =SUM(I20:I24) -> 37584600 | K25: =SUM(K20:K24) -> 22300000
A27: LOS 40 - VIDEO SECCIONES PLUS
A28: MARCA | B28: CIUDAD | C28: PRODUCTO | D28: VALORIZACION | E28: VALOR VEZ | F28: VECES DIA | G28: No DIAS | H28: TOTAL | I28: VALOR BTO | J28: DTO | K28: VALOR NETO
A29: BÉSAME | B29: BOGOTÁ | C29: MORNING | D29: SECCION ESPECIAL (RADIO) | E29: 6188600 | F29: 1 | G29: 1 | H29: =F29*G29 -> 1 | I29: =H29*E29 -> 6188600 | J29: 0.8 | K29: =I29-(I29*J29) -> 1237720
A30: BÉSAME | B30: DIGITAL | C30: DIGITAL | D30: PRODUCCIÓN CAPSULA DE VIDEO | E30: 2280000 | F30: 1 | G30: 1 | H30: =F30*G30 -> 1 | I30: =H30*E30 -> 2280000 | J30: 0 | K30: =I30-(I30*J30) -> 2280000
A31: BÉSAME | B31: DIGITAL | C31: DIGITAL | D31: REEL IG (PUBLICACIÓN) | E31: 8892000 | F31: 1 | G31: 1 | H31: =F31*G31 -> 1 | I31: =H31*E31 -> 8892000 | J31: 0.35 | K31: =I31-(I31*J31) -> 5779800
A32: BÉSAME | B32: DIGITAL | C32: DIGITAL | D32: VIDEO TIK TOK (PUBLICACIÓN) | E32: 15048000 | F32: 1 | G32: 1 | H32: =F32*G32 -> 1 | I32: =H32*E32 -> 15048000 | J32: 0.35 | K32: =I32-(I32*J32) -> 9781200
A33: BÉSAME | B33: DIGITAL | C33: DIGITAL | D33: DESARROLLO SECCIÓN PLUS | E33: 8000000 | F33: 1 | G33: 1 | H33: =F33*G33 -> 1 | I33: =H33*E33 -> 8000000 | J33: 0.00984 | K33: =I33-(I33*J33) -> 7921280
I34: =SUM(I29:I33) -> 40408600 | K34: =SUM(K29:K33) -> 27000000
A36: RADIOACKTIVA - VIDEO SECCIONES EL GALLO
A37: MARCA | B37: CIUDAD | C37: PRODUCTO | D37: VALORIZACION | E37: VALOR VEZ | F37: VECES DIA | G37: No DIAS | H37: TOTAL | I37: VALOR BTO | J37: DTO | K37: VALOR NETO | L37: 0.14 | M37: 0.1
A38: RADIOACKTIVA | B38: NACIONAL | C38: MORNING | D38: SECCION ESPECIAL(RADIO) | E38: =M38 -> 6188600 | F38: 1 | G38: 1 | H38: =F38*G38 -> 1 | I38: =H38*E38 -> 6188600 | J38: 0.59947861 | K38: =I38-(I38*J38) -> 2478666.7 | M38: =5626000+(5626000*M37) -> 6188600
A39: RADIOACKTIVA | B39: DIGITAL | C39: DIGITAL | D39: PRODUCCIÓN CAPSULA DE VIDEO | E39: =L39 -> 2280000 | F39: 1 | G39: 1 | H39: =F39*G39 -> 1 | I39: =H39*E39 -> 2280000 | J39: 0 | K39: =I39-(I39*J39) -> 2280000 | L39: =2000000+(2000000*L37) -> 2280000
A40: RADIOACKTIVA | B40: DIGITAL | C40: DIGITAL | D40: REEL IG (PUBLICACIÓN) | E40: 2500000 | F40: 1 | G40: 1 | H40: =F40*G40 -> 1 | I40: =H40*E40 -> 2500000 | J40: 0.5 | K40: =I40-(I40*J40) -> 1250000 | L40: =2160000+(2160000*L37) -> 2462400
A41: RADIOACKTIVA | B41: DIGITAL | C41: DIGITAL | D41: VIDEO TIK TOK (PUBLICACIÓN) | E41: 7000000 | F41: 1 | G41: 1 | H41: =F41*G41 -> 1 | I41: =H41*E41 -> 7000000 | J41: 0.51552381 | K41: =I41-(I41*J41) -> 3391333.3 | L41: =6000000+(6000000*L37) -> 6840000
I42: =SUM(I38:I41) -> 17968600 | K42: =SUM(K38:K41) -> 9400000
A44: RADIOACKTIVA - VIDEO SECCIONES CON PRODUCT PLACEMENT SIN INTERACCIÓN - (Cliente entrega el producto)
A45: MARCA | B45: CIUDAD | C45: PRODUCTO | D45: VALORIZACION | E45: VALOR VEZ | F45: VECES DIA | G45: No DIAS | H45: TOTAL | I45: VALOR BTO | J45: DTO | K45: VALOR NETO | L45: 0.14 | M45: 0.1
...

Sheet Video Franquicia
B3: PROBANDO PROBANDO CARACOL VIDEO CORTO
B4: MARCA | C4: PRODUCTO | D4: VALORIZACION | E4: VALOR VEZ | F4: VECES DIA | G4: No DIAS | H4: TOTAL | I4: VALOR BTO | J4: DTO | K4: VALOR NETO
B5: CARACOL | C5: RADIO | D5: DOS PUNTOS | E5: 6000000 | F5: 3 | G5: 1 | H5: =F5*G5 -> 3 | I5: =H5*E5 -> 18000000 | J5: 0.78 | K5: =I5-(I5*J5) -> 3960000
B6: CARACOL | C6: RADIO | D6: LUCIÉRNAGA | E6: 10300000 | F6: 3 | G6: 1 | H6: =F6*G6 -> 3 | I6: =H6*E6 -> 30900000 | J6: 0.78 | K6: =I6-(I6*J6) -> 6798000
B7: CARACOL | C7: RADIO | D7: A VIVIR FDS | E7: 3280000 | F7: 3 | G7: 1 | H7: =F7*G7 -> 3 | I7: =H7*E7 -> 9840000 | J7: 0.78 | K7: =I7-(I7*J7) -> 2164800
B8: CARACOL | C8: DIGITAL | D8: PRODUCCIÓN CAPSULA DE VIDEO | E8: 8000000 | F8: 1 | G8: 1 | H8: =F8*G8 -> 1 | I8: =H8*E8 -> 8000000 | J8: 0.09035 | K8: =I8-(I8*J8) -> 7277200
B9: CARACOL | C9: DIGITAL | D9: REEL IG (PUBLICACIÓN) | E9: 4000000 | F9: 1 | G9: 1 | H9: =F9*G9 -> 1 | I9: =H9*E9 -> 4000000 | J9: 0.4 | K9: =I9-(I9*J9) -> 2400000
B10: CARACOL | C10: DIGITAL | D10: VIDEO TIK TOK (PUBLICACIÓN) | E10: 4000000 | F10: 1 | G10: 1 | H10: =F10*G10 -> 1 | I10: =H10*E10 -> 4000000 | J10: 0.4 | K10: =I10-(I10*J10) -> 2400000
I11: =SUM(I5:I10) -> 74740000 | K11: =SUM(K5:K10) -> 25000000
B14: ENTENDENCIA CARACOL VIDEO CORTO
B15: MARCA | C15: PRODUCTO | D15: VALORIZACION | E15: VALOR VEZ | F15: VECES DIA | G15: No DIAS | H15: TOTAL | I15: VALOR BTO | J15: DTO | K15: VALOR NETO
B16: CARACOL | C16: RADIO | D16: DOS PUNTOS | E16: 6000000 | F16: 3 | G16: 1 | H16: =F16*G16 -> 3 | I16: =H16*E16 -> 18000000 | J16: 0.78 | K16: =I16-(I16*J16) -> 3960000
B17: CARACOL | C17: RADIO | D17: LUCIÉRNAGA | E17: 10300000 | F17: 3 | G17: 1 | H17: =F17*G17 -> 3 | I17: =H17*E17 -> 30900000 | J17: 0.78 | K17: =I17-(I17*J17) -> 6798000
B18: CARACOL | C18: RADIO | D18: A VIVIR FDS | E18: 3280000 | F18: 3 | G18: 1 | H18: =F18*G18 -> 3 | I18: =H18*E18 -> 9840000 | J18: 0.78 | K18: =I18-(I18*J18) -> 2164800
B19: CARACOL | C19: DIGITAL | D19: PRODUCCIÓN CAPSULA DE VIDEO | E19: 8000000 | F19: 1 | G19: 1 | H19: =F19*G19 -> 1 | I19: =H19*E19 -> 8000000 | J19: 0.09035 | K19: =I19-(I19*J19) -> 7277200
B20: CARACOL | C20: DIGITAL | D20: REEL IG (PUBLICACIÓN) | E20: 4000000 | F20: 1 | G20: 1 | H20: =F20*G20 -> 1 | I20: =H20*E20 -> 4000000 | J20: 0.4 | K20: =I20-(I20*J20) -> 2400000
B21: CARACOL | C21: DIGITAL | D21: VIDEO TIK TOK (PUBLICACIÓN) | E21: 4000000 | F21: 1 | G21: 1 | H21: =F21*G21 -> 1 | I21: =H21*E21 -> 4000000 | J21: 0.4 | K21: =I21-(I21*J21) -> 2400000
I22: =SUM(I16:I21) -> 74740000 | K22: =SUM(K16:K21) -> 25000000
B25: TECNOLOGÍA CARACOL VIDEO CORTO
B26: MARCA | C26: PRODUCTO | D26: VALORIZACION | E26: VALOR VEZ | F26: VECES DIA | G26: No DIAS | H26: TOTAL | I26: VALOR BTO | J26: DTO | K26: VALOR NETO
B27: CARACOL | C27: RADIO | D27: DOS PUNTOS | E27: 6000000 | F27: 3 | G27: 1 | H27: =F27*G27 -> 3 | I27: =H27*E27 -> 18000000 | J27: 0.78 | K27: =I27-(I27*J27) -> 3960000
B28: CARACOL | C28: RADIO | D28: LUCIÉRNAGA | E28: 10300000 | F28: 3 | G28: 1 | H28: =F28*G28 -> 3 | I28: =H28*E28 -> 30900000 | J28: 0.78 | K28: =I28-(I28*J28) -> 6798000
B29: CARACOL | C29: RADIO | D29: A VIVIR FDS | E29: 3280000 | F29: 3 | G29: 1 | H29: =F29*G29 -> 3 | I29: =H29*E29 -> 9840000 | J29: 0.78 | K29: =I29-(I29*J29) -> 2164800
B30: CARACOL | C30: DIGITAL | D30: PRODUCCIÓN CAPSULA DE VIDEO | E30: 8000000 | F30: 1 | G30: 1 | H30: =F30*G30 -> 1 | I30: =H30*E30 -> 8000000 | J30: 0.09035 | K30: =I30-(I30*J30) -> 7277200
B31: CARACOL | C31: DIGITAL | D31: REEL IG (PUBLICACIÓN) | E31: 4000000 | F31: 1 | G31: 1 | H31: =F31*G31 -> 1 | I31: =H31*E31 -> 4000000 | J31: 0.4 | K31: =I31-(I31*J31) -> 2400000
B32: CARACOL | C32: DIGITAL | D32: VIDEO TIK TOK (PUBLICACIÓN) | E32: 4000000 | F32: 1 | G32: 1 | H32: =F32*G32 -> 1 | I32: =H32*E32 -> 4000000 | J32: 0.4 | K32: =I32-(I32*J32) -> 2400000
I33: =SUM(I27:I32) -> 74740000 | K33: =SUM(K27:K32) -> 25000000
B36: CHECK IN CARACOL VIDEO CORTO
B37: MARCA | C37: PRODUCTO | D37: VALORIZACION | E37: VALOR VEZ | F37: VECES DIA | G37: No DIAS | H37: TOTAL | I37: VALOR BTO | J37: DTO | K37: VALOR NETO
B38: CARACOL | C38: RADIO | D38: DOS PUNTOS | E38: 6000000 | F38: 3 | G38: 1 | H38: =F38*G38 -> 3 | I38: =H38*E38 -> 18000000 | J38: 0.78 | K38: =I38-(I38*J38) -> 3960000
B39: CARACOL | C39: RADIO | D39: LUCIÉRNAGA | E39: 10300000 | F39: 3 | G39: 1 | H39: =F39*G39 -> 3 | I39: =H39*E39 -> 30900000 | J39: 0.78 | K39: =I39-(I39*J39) -> 6798000
B40: CARACOL | C40: RADIO | D40: A VIVIR FDS | E40: 3280000 | F40: 3 | G40: 1 | H40: =F40*G40 -> 3 | I40: =H40*E40 -> 9840000 | J40: 0.78 | K40: =I40-(I40*J40) -> 2164800
B41: CARACOL | C41: DIGITAL | D41: PRODUCCIÓN CAPSULA DE VIDEO | E41: 8000000 | F41: 1 | G41: 1 | H41: =F41*G41 -> 1 | I41: =H41*E41 -> 8000000 | J41: 0.09035 | K41: =I41-(I41*J41) -> 7277200
B42: CARACOL | C42: DIGITAL | D42: REEL IG (PUBLICACIÓN) | E42: 4000000 | F42: 1 | G42: 1 | H42: =F42*G42 -> 1 | I42: =H42*E42 -> 4000000 | J42: 0.4 | K42: =I42-(I42*J42) -> 2400000
B43: CARACOL | C43: DIGITAL | D43: VIDEO TIK TOK (PUBLICACIÓN) | E43: 4000000 | F43: 1 | G43: 1 | H43: =F43*G43 -> 1 | I43: =H43*E43 -> 4000000 | J43: 0.4 | K43: =I43-(I43*J43) -> 2400000
I44: =SUM(I38:I43) -> 74740000 | K44: =SUM(K38:K43) -> 25000000
B46: EN TERRITORIO / YO SÉ QUIÉN SABE LO QUE UD NO SABE… CON VINO CARACOL VIDEO LARGO / /La hemeroteca / El Reportero Caracol / Preguntas cultura General
B47: MARCA | C47: PRODUCTO | D47: VALORIZACION | E47: VALOR VEZ | F47: VECES DIA | G47: No DIAS | H47: TOTAL | I47: VALOR BTO | J47: DTO | K47: VALOR NETO
B48: CARACOL | C48: RADIO | D48: DOS PUNTOS | E48: 6000000 | F48: 0 | G48: 1 | H48: =F48*G48 -> 0 | I48: =H48*E48 -> 0 | J48: 0.78 | K48: =I48-(I48*J48) -> 0
B49: CARACOL | C49: RADIO | D49: LUCIÉRNAGA | E49: 10300000 | F49: 0 | G49: 1 | H49: =F49*G49 -> 0 | I49: =H49*E49 -> 0 | J49: 0.78 | K49: =I49-(I49*J49) -> 0
...

Sheet Video Remoto (Corto)
A1: LOS40 VIDEO REMOTO (BOG)
A2: MARCA | B2: CIUDAD | C2: PRODUCTO | D2: VALORIZACION | E2: VALOR VEZ | F2: VECES DIA | G2: No DIAS | H2: TOTAL | I2: VALOR BTO | J2: DTO | K2: VALOR NETO | L2: 0.14
A3: LOS40 | B3: BOGOTÁ | C3: MUSICAL | D3: REMOTO | E3: 12650000 | F3: 1 | G3: 1 | H3: 1 | I3: =E3*F3 -> 12650000 | J3: 0 | K3: =I3-I3*J3 -> 12650000
A4: LOS40 | B4: DIGITAL | C4: DIGITAL | D4: VIDEO REMOTO | E4: 3790000 | F4: 1 | G4: 1 | H4: 1 | I4: =E4*F4 -> 3790000 | J4: 0 | K4: =I4-I4*J4 -> 3790000 | L4: =3448800+(3448800*L2) -> 3931632
I5: =SUM(I3:I4) -> 16440000 | K5: =SUM(K3:K4) -> 16440000
A7: LOS40 VIDEO REMOTO (MEDELLIN)
A8: MARCA | B8: CIUDAD | C8: PRODUCTO | D8: VALORIZACION | E8: VALOR VEZ | F8: VECES DIA | G8: No DIAS | H8: TOTAL | I8: VALOR BTO | J8: DTO | K8: VALOR NETO | L8: 0.14
A9: LOS40 | B9: MEDELLIN | C9: MUSICAL | D9: REMOTO | E9: 6320000 | F9: 1 | G9: 1 | H9: 1 | I9: =E9*F9 -> 6320000 | J9: 0 | K9: =I9-I9*J9 -> 6320000
A10: LOS40 | B10: DIGITAL | C10: DIGITAL | D10: VIDEO REMOTO | E10: 1900000 | F10: 1 | G10: 1 | H10: 1 | I10: =E10*F10 -> 1900000 | J10: 0 | K10: =I10-I10*J10 -> 1900000 | L10: =1724400+(1724400*L8) -> 1965816
I11: =SUM(I9:I10) -> 8220000 | K11: =SUM(K9:K10) -> 8220000
A13: LOS40 VIDEO REMOTO (CALI)
A14: MARCA | B14: CIUDAD | C14: PRODUCTO | D14: VALORIZACION | E14: VALOR VEZ | F14: VECES DIA | G14: No DIAS | H14: TOTAL | I14: VALOR BTO | J14: DTO | K14: VALOR NETO | L14: 0.14
A15: LOS40 | B15: CALI | C15: MUSICAL | D15: REMOTO | E15: 5690000 | F15: 1 | G15: 1 | H15: 1 | I15: =E15*F15 -> 5690000 | J15: 0 | K15: =I15-I15*J15 -> 5690000
A16: LOS40 | B16: DIGITAL | C16: DIGITAL | D16: VIDEO REMOTO | E16: 1710000 | F16: 1 | G16: 1 | H16: 1 | I16: =E16*F16 -> 1710000 | J16: 0 | K16: =I16-I16*J16 -> 1710000 | L16: =1552200+(1552200*L14) -> 1769508
I17: =SUM(I15:I16) -> 7400000 | K17: =SUM(K15:K16) -> 7400000
A20: RADIOACKTIVA VIDEO REMOTO (BOG)
A21: MARCA | B21: CIUDAD | C21: PRODUCTO | D21: VALORIZACION | E21: VALOR VEZ | F21: VECES DIA | G21: No DIAS | H21: TOTAL | I21: VALOR BTO | J21: DTO | K21: VALOR NETO | L21: 0.14
A22: RADIOACKTIVA | B22: BOGOTÁ | C22: MUSICAL | D22: REMOTO | E22: 16900000 | F22: 1 | G22: 1 | H22: 1 | I22: =E22*F22 -> 16900000 | J22: -0.0019138133 | K22: =I22-I22*J22 -> 16932343
A23: RADIOACKTIVA | B23: DIGITAL | C23: DIGITAL | D23: VIDEO REMOTO | E23: =L23 -> 5253804 | F23: 1 | G23: 1 | H23: 1 | I23: =E23*F23 -> 5253804 | J23: 0.0068802424 | K23: =I23-I23*J23 -> 5217656.6 | L23: =4608600+(4608600*L21) -> 5253804
I24: =SUM(I22:I23) -> 22153804 | K24: =SUM(K22:K23) -> 22150000
A26: RADIOACKTIVA VIDEO REMOTO (MEDELLIN)
A27: MARCA | B27: CIUDAD | C27: PRODUCTO | D27: VALORIZACION | E27: VALOR VEZ | F27: VECES DIA | G27: No DIAS | H27: TOTAL | I27: VALOR BTO | J27: DTO | K27: VALOR NETO | L27: 0.14
A28: RADIOACKTIVA | B28: MEDELLIN | C28: MUSICAL | D28: REMOTO | E28: 7450000 | F28: 1 | G28: 1 | H28: 1 | I28: =E28*F28 -> 7450000 | J28: 0 | K28: =I28-I28*J28 -> 7450000
A29: RADIOACKTIVA | B29: DIGITAL | C29: DIGITAL | D29: VIDEO REMOTO | E29: =L29 -> 2317734 | F29: 1 | G29: 1 | H29: 1 | I29: =E29*F29 -> 2317734 | J29: 0.0076514389 | K29: =I29-I29*J29 -> 2300000 | L29: =2033100+(2033100*L27) -> 2317734
I30: =SUM(I28:I29) -> 9767734 | K30: =SUM(K28:K29) -> 9750000
A33: TROPICANA VIDEO REMOTO (BOG)
A34: MARCA | B34: CIUDAD | C34: PRODUCTO | D34: VALORIZACION | E34: VALOR VEZ | F34: VECES DIA | G34: No DIAS | H34: TOTAL | I34: VALOR BTO | J34: DTO | K34: VALOR NETO | L34: 0.14
A35: TROPICANA | B35: BOGOTÁ | C35: MUSICAL | D35: REMOTO | E35: 20290000 | F35: 1 | G35: 1 | H35: 1 | I35: =E35*F35 -> 20290000 | J35: -2.178413e-05 | K35: =I35-I35*J35 -> 20290442
A36: TROPICANA | B36: DIGITAL | C36: DIGITAL | D36: VIDEO REMOTO | E36: =L36 -> 6309558 | F36: 1 | G36: 1 | H36: 1 | I36: =E36*F36 -> 6309558 | J36: 0 | K36: =I36-I36*J36 -> 6309558 | L36: =5534700+(5534700*L34) -> 6309558
I37: =SUM(I35:I36) -> 26599558 | K37: =SUM(K35:K36) -> 26600000
A39: TROPICANA VIDEO REMOTO (MEDELLIN)
A40: MARCA | B40: CIUDAD | C40: PRODUCTO | D40: VALORIZACION | E40: VALOR VEZ | F40: VECES DIA | G40: No DIAS | H40: TOTAL | I40: VALOR BTO | J40: DTO | K40: VALOR NETO | L40: 0.14
A41: TROPICANA | B41: MEDELLIN | C41: MUSICAL | D41: REMOTO | E41: 9370000 | F41: 1 | G41: 1 | H41: 1 | I41: =E41*F41 -> 9370000 | J41: 0 | K41: =I41-I41*J41 -> 9370000
A42: TROPICANA | B42: DIGITAL | C42: DIGITAL | D42: VIDEO REMOTO | E42: =L42 -> 2911788 | F42: 1 | G42: 1 | H42: 1 | I42: =E42*F42 -> 2911788 | J42: 0.010917004 | K42: =I42-I42*J42 -> 2880000 | L42: =2554200+(2554200*L40) -> 2911788
I43: =SUM(I41:I42) -> 12281788 | K43: =SUM(K41:K42) -> 12250000
A45: TROPICANA VIDEO REMOTO (CALI)
A46: MARCA | B46: CIUDAD | C46: PRODUCTO | D46: VALORIZACION | E46: VALOR VEZ | F46: VECES DIA | G46: No DIAS | H46: TOTAL | I46: VALOR BTO | J46: DTO | K46: VALOR NETO | L46: 0.14
A47: TROPICANA | B47: CALI | C47: MUSICAL | D47: REMOTO | E47: 9370000 | F47: 1 | G47: 1 | H47: 1 | I47: =E47*F47 -> 9370000 | J47: 0 | K47: =I47-I47*J47 -> 9370000
A48: TROPICANA | B48: DIGITAL | C48: DIGITAL | D48: VIDEO REMOTO | E48: =L48 -> 2911788 | F48: 1 | G48: 1 | H48: 1 | I48: =E48*F48 -> 2911788 | J48: 0.010917004 | K48: =I48-I48*J48 -> 2880000 | L48: =2554200+(2554200*L46) -> 2911788
I49: =SUM(I47:I48) -> 12281788 | K49: =SUM(K47:K48) -> 12250000
...

Sheet Seccion Prime - BM - Spot
C4: SECCIÓN PRIME
B6: SECCIÓN PRIME | E6: TROPICANA | F6: BÉSAME | G6: RADIOACKTIVA | H6: LOS 40
B7: Sección video Prime (En vivo - Live, Banner, Full Screen) | C7: MODELO / FORMATO | D7: CONTENIDO | E7: 1380000 | F7: 1220000 | G7: 1440000 | H7: 2980000
B8: Digital (marca + YouTube + video) | C8: YOUTUBE | D8: VIDEO | E8: 414000 | F8: 366000 | G8: 432000 | H8: 894000
B9: Digital (marca + Tiktok + video) | C9: TIKTOK | D9: VIDEO | E9: 759000 | F9: 671000 | G9: 792000 | H9: 1639000
B10: Radio (emisora + programa + sección) | C10: PROGRAMA | D10: SECCION | E10: 207000 | F10: 183000 | G10: 216000 | H10: 447000
C14: BRANDED MOMENTS
C15: Tarifa Bruta | D15: VECES AL DÍA | E15: Días | F15: Impactos | G15: Total Bruto | H15: Dcto | I15: Total Neto
B16: LOS 40 | C16: 4400000 | D16: 3 | E16: 11 | F16: =D16*E16 -> 33 | G16: =E16*C16 -> 48400000 | H16: 0.2 | I16: =G16-(G16*H16) -> 38720000
C17: 4400000 | D17: 1 | E17: 1 | F17: 3 | G17: =E17*C17 -> 4400000 | H17: 0 | I17: =G17-(G17*H17) -> 4400000
B18: MUSICALES | C18: 2400000 | D18: 3 | E18: 11 | F18: =D18*E18 -> 33 | G18: =E18*C18 -> 26400000 | H18: 0.2 | I18: =G18-(G18*H18) -> 21120000
C19: 2400000 | D19: 1 | E19: 1 | F19: 3 | G19: =E19*C19 -> 2400000 | H19: 0 | I19: =G19-(G19*H19) -> 2400000
C20: 4400000 | D20: 1 | E20: 11 | F20: =D20*E20 -> 11 | G20: =F20*C20 -> 48400000 | H20: 0.2 | I20: =G20-(G20*H20) -> 38720000
B21: CRC / AS Colombia: Rock & Gol del AS / Banqueados / Rock & Gol del AS Transmisión FDS / La Jugada Bacana | C21: 2400000 | D21: 3 | E21: 11 | F21: =D21*E21 -> 33 | G21: =E21*C21 -> 26400000 | H21: 0.2 | I21: =G21-(G21*H21) -> 21120000
B24: BRANDED MOMENTS | E24: TROPICANA | F24: BÉSAME | G24: RADIOACKTIVA | H24: LOS 40 | I24: CRC / AS
B25: Branded Moments (Animados, Toma de Cabina, Product Placement) | C25: MODELO / FORMATO | D25: CONTENIDO | E25: 2400000 | F25: 2400000 | G25: 2400000 | H25: 4400000 | I25: 2400000
B26: (3 veces en el día)
B27: Digital (marca + YouTube + video) | C27: YOUTUBE | D27: VIDEO | E27: 720000 | F27: 720000 | G27: 720000 | H27: 1320000 | I27: 720000
B28: Digital (marca + Tiktok + video) | C28: TIKTOK | D28: VIDEO | E28: 1680000 | F28: 1680000 | G28: 1680000 | H28: 3080000 | I28: 1680000
B31: SPOT | E31: TROPICANA | F31: BÉSAME | G31: RADIOACKTIVA | H31: LOS 40
B32: Spot * 3 (3 veces en el día) | C32: MODELO / FORMATO | D32: CONTENIDO | E32: 1656000 | F32: 1464000 | G32: 1728000 | H32: 3576000
B33: Digital (marca + YouTube + video) | C33: YOUTUBE | D33: VIDEO | E33: 496800 | F33: 439200 | G33: 518400 | H33: 1072800
B34: Digital (marca + Tiktok + video) | C34: TIKTOK | D34: VIDEO | E34: 1159200 | F34: 1024800 | G34: 1209600 | H34: 2503200
B38: SPOT MOMENTS | E38: TROPICANA | F38: BÉSAME | G38: RADIOACKTIVA | H38: LOS 40
B39: Spot Moments * 3 (3 veces en el día) | C39: MODELO / FORMATO | D39: CONTENIDO | E39: 4056000 | F39: 3864000 | G39: 4128000 | H39: 7976000
B40: Digital (marca + YouTube + video) | C40: YOUTUBE | D40: VIDEO | E40: 1216800 | F40: 1159200 | G40: 1238400 | H40: 2392800
B41: Digital (marca + Tiktok + video) | C41: TIKTOK | D41: VIDEO | E41: 2839200 | F41: 2704800 | G41: 2889600 | H41: 5583200

Sheet Contenido Exclusivo
A2: CONTENIDO EXCLUSIVO IMPRESENTABLES (1 SALIDA) EN CABINA 2026
A3: Salida con vocero de marca de max 20 mins. Minimo de duración depende del vocero de marca segun el desarrolle que se logre al aire.
A4: MARCA | B4: CIUDAD | C4: PRODUCTO | D4: VALORIZACION | E4: VALOR VEZ | F4: VECES DIA | G4: No DIAS | H4: TOTAL | I4: VALOR BTO | J4: DTO | K4: VALOR NETO
A5: LOS40 | B5: NACIONAL | C5: IMPRESENTABLES | D5: CONTENIDO EXCLUSIVO (EN VIVO EN RADIO) | E5: 12828000 | F5: 1 | G5: 1 | H5: 1 | I5: 12828000 | J5: 0.47 | K5: 6860000
A6: LOS40 | B6: DIGITAL | C6: DIGITAL | D6: LIVE TIK TOK | E6: 12000000 | F6: 1 | G6: 1 | H6: 1 | I6: 12000000 | J6: 0.47 | K6: 6420000
A7: LOS40 | B7: DIGITAL | C7: DIGITAL | D7: CAPSULA DE VIDEO (PRODUCCIÓN) | E7: 2280000 | F7: 1 | G7: 1 | H7: 1 | I7: 2280000 | J7: 0 | K7: 2280000
A8: LOS40 | B8: DIGITAL | C8: DIGITAL | D8: VIDEO HORIZONTAL YOUTUBE (PUBLICACIÓN) | E8: 11000000 | F8: 1 | G8: 1 | H8: 1 | I8: 11000000 | J8: 0.46 | K8: 5940000
A9: LOS40 | B9: DIGITAL | C9: DIGITAL | D9: REEL IG (PUBLICACIÓN) | E9: 9000000 | F9: 1 | G9: 1 | H9: 1 | I9: 9000000 | J9: 0.46 | K9: 4842000
A10: LOS40 | B10: DIGITAL | C10: DIGITAL | D10: VIDEO TIK TOK (PUBLICACIÓN) | E10: 15100000 | F10: 1 | G10: 1 | H10: 1 | I10: 15100000 | J10: 0.46 | K10: 8154000
I11: 23840000 | K11: 34496000
K12: 34500
A14: CONTENIDO EXCLUSIVO INEXPERTAS (1 SALIDA) EN CABINA 2026
A15: Salida con vocero de marca de max 20 mins. Minimo de duración depende del vocero de marca segun el desarrolle que se logre al aire.
A16: MARCA | B16: CIUDAD | C16: PRODUCTO | D16: VALORIZACION | E16: VALOR VEZ | F16: VECES DIA | G16: No DIAS | H16: TOTAL | I16: VALOR BTO | J16: DTO | K16: VALOR NETO
A17: BÉSAME | B17: BOGOTA | C17: INEXPERTAS | D17: CONTENIDO EXCLUSIVO (EN VIVO EN RADIO) | E17: 4556000 | F17: 1 | G17: 1 | H17: 1 | I17: 4556000 | J17: 0.47 | K17: 2436402
A18: BÉSAME | B18: DIGITAL | C18: DIGITAL | D18: LIVE TIK TOK | E18: 3900000 | F18: 1 | G18: 1 | H18: 1 | I18: 3900000 | J18: 0 | K18: 3900000
A19: BÉSAME | B19: DIGITAL | C19: DIGITAL | D19: CAPSULA DE VIDEO (PRODUCCIÓN) | E19: 2400000 | F19: 1 | G19: 1 | H19: 1 | I19: 2400000 | J19: 0 | K19: 2400000
A20: BÉSAME | B20: DIGITAL | C20: DIGITAL | D20: VIDEO HORIZONTAL YOUTUBE (PUBLICACIÓN) | E20: 2800000 | F20: 1 | G20: 1 | H20: 1 | I20: 2800000 | J20: 0.4 | K20: 1680000
A21: BÉSAME | B21: DIGITAL | C21: DIGITAL | D21: REEL IG (PUBLICACIÓN) | E21: 1700000 | F21: 1 | G21: 1 | H21: 1 | I21: 1700000 | J21: 0.4 | K21: 1020000
A22: BÉSAME | B22: DIGITAL | C22: DIGITAL | D22: VIDEO TIK TOK (PUBLICACIÓN) | E22: 2500000 | F22: 1 | G22: 1 | H22: 1 | I22: 2500000 | J22: 0.4 | K22: 1500000
I23: 23840000 | K23: 12936402 | L23: 13
A26: CONTENIDO EXCLUSIVO TROPICANA (1 SALIDA) EN CABINA 2026
A27: Salida con vocero de marca de max 20 mins. Minimo de duración depende del vocero de marca segun el desarrolle que se logre al aire.
A28: MARCA | B28: CIUDAD | C28: PRODUCTO | D28: VALORIZACION | E28: VALOR VEZ | F28: VECES DIA | G28: No DIAS | H28: TOTAL | I28: VALOR BTO | J28: DTO | K28: VALOR NETO
A29: TROPICANA | B29: BOGOTA | C29: INEXPERTAS | D29: CONTENIDO EXCLUSIVO (EN VIVO EN RADIO) | E29: 8280000 | F29: 1 | G29: 1 | H29: 1 | I29: 8280000 | J29: 0.47 | K29: 4427877
A30: TROPICANA | B30: DIGITAL | C30: DIGITAL | D30: LIVE TIK TOK | E30: 3500000 | F30: 1 | G30: 1 | H30: 1 | I30: 3500000 | J30: 0 | K30: 3500000
A31: TROPICANA | B31: DIGITAL | C31: DIGITAL | D31: CAPSULA DE VIDEO (PRODUCCIÓN) | E31: 2400000 | F31: 1 | G31: 1 | H31: 1 | I31: 2400000 | J31: 0 | K31: 2400000
A32: TROPICANA | B32: DIGITAL | C32: DIGITAL | D32: VIDEO HORIZONTAL YOUTUBE (PUBLICACIÓN) | E32: 8000000 | F32: 1 | G32: 1 | H32: 1 | I32: 8000000 | J32: 0.4 | K32: 4800000
A33: TROPICANA | B33: DIGITAL | C33: DIGITAL | D33: REEL IG (PUBLICACIÓN) | E33: 1700000 | F33: 1 | G33: 1 | H33: 1 | I33: 1700000 | J33: 0.4 | K33: 1020000
A34: TROPICANA | B34: DIGITAL | C34: DIGITAL | D34: VIDEO TIK TOK (PUBLICACIÓN) | E34: 2500000 | F34: 1 | G34: 1 | H34: 1 | I34: 2500000 | J34: 0.4 | K34: 1500000
I35: 23840000 | K35: 17647877
A39: CONTENIDO EXCLUSIVOEL GALLO (1 SALIDA) EN CABINA 2026 CON VOCERO
A40: Salida con vocero de marca de max 20 mins. Minimo de duración depende del vocero de marca segun el desarrolle que se logre al aire.
A41: MARCA | B41: CIUDAD | C41: PRODUCTO | D41: VALORIZACION | E41: VALOR VEZ | F41: VECES DIA | G41: No DIAS | H41: TOTAL | I41: VALOR BTO | J41: DTO | K41: VALOR NETO
A42: RADIOACKTIVA | B42: NACIONAL | C42: EL GALLO | D42: CONTENIDO EXCLUSIVO (EN VIVO EN RADIO) | E42: 10160000 | F42: 1 | G42: 1 | H42: 1 | I42: 10160000 | J42: 0.47 | K42: 5433240
A43: RADIOACKTIVA | B43: DIGITAL | C43: DIGITAL | D43: LIVE TIK TOK | E43: 4500000 | F43: 1 | G43: 1 | H43: 1 | I43: 4500000 | J43: 0 | K43: 4500000
A44: RADIOACKTIVA | B44: DIGITAL | C44: DIGITAL | D44: PRODUCCIÓN CAPSULA DE VIDEO | E44: 2280000 | F44: 1 | G44: 1 | H44: 1 | I44: 2280000 | J44: 0 | K44: 2280000
A45: RADIOACKTIVA | B45: DIGITAL | C45: DIGITAL | D45: REEL IG (PUBLICACIÓN) | E45: 2462400 | F45: 1 | G45: 1 | H45: 1 | I45: 2462400 | J45: 0.52 | K45: 1181952
A46: RADIOACKTIVA | B46: DIGITAL | C46: DIGITAL | D46: VIDEO TIK TOK (PUBLICACIÓN) | E46: 6840000 | F46: 1 | G46: 1 | H46: 1 | I46: 6840000 | J46: 0.52 | K46: 3317400
A47: RADIOACKTIVA | B47: DIGITAL | C47: DIGITAL | D47: VIDEO HORIZONTAL YOUTUBE (PUBLICACIÓN) | E47: 7000000 | F47: 1 | G47: 1 | H47: 1 | I47: 7000000 | J47: 0.5 | K47: 3486000
...

Sheet Microprograma
A2: MICROPROGRAMA BÉSAME INEXPERTAS CON VOCERO DE MARCA
A3: MARCA | B3: CIUDAD | C3: PRODUCTO | D3: VALORIZACION | E3: BRUTO | F3: VECES DIA | G3: No DIAS | H3: TOTAL | I3: VALOR BTO | J3: DTO | K3: VALOR NETO
A4: BÉSAME | B4: BOGOTÁ | C4: MICROPROGRAMA | D4: PRESENTACIÓN Y DESPEDIDA DEL MICROPROGRAMA | E4: 1139000 | F4: 1 | G4: 1 | H4: 1 | I4: 1139000 | J4: 0.75 | K4: 284750
A5: BÉSAME | B5: BOGOTÁ | C5: MICROPROGRAMA | D5: SECCIÓN ESPECIAL INEXPERTAS | E5: 2278000 | F5: 2 | G5: 1 | H5: 2 | I5: 4556000 | J5: 0.75 | K5: 1139000
A6: BÉSAME | B6: BOGOTÁ | C6: MICROPROGRAMA | D6: CUÑAS HASTA DE 20" MORNING | E6: 477000 | F6: 4 | G6: 1 | H6: 4 | I6: 1908000 | J6: 0.75 | K6: 477000
A7: BÉSAME | B7: BOGOTÁ | C7: MICROPROGRAMA | D7: CUÑA HASTA DE 20" MUSICAL | E7: 417000 | F7: 6 | G7: 1 | H7: 6 | I7: 2502000 | J7: 0.75 | K7: 625500
A8: BÉSAME | B8: BOGOTÁ | C8: MICROPROGRAMA | D8: PROMO 30'' PROGRAMACIÓN MUSICAL | E8: 278000 | F8: 10 | G8: 1 | H8: 10 | I8: 2780000 | J8: 0.75 | K8: 695000
A9: BÉSAME | B9: BOGOTÁ | C9: MICROPROGRAMA | D9: INDIVIDUALES PROGRAMACIÓN MUSICAL | E9: 779000 | F9: 4 | G9: 1 | H9: 4 | I9: 3116000 | J9: 0.75 | K9: 779000
A10: MICROPROGRAMA DETALLE DIGITAL (VIDEO SECCIÓN)
A11: BÉSAME | B11: BOGOTÁ | C11: MORNING | D11: SECCION ESPECIAL (RADIO) | E11: 3416400 | F11: 1 | G11: 1 | H11: 1 | I11: 3416400 | J11: 0.8 | K11: 683280
A12: BÉSAME | B12: DIGITAL | C12: DIGITAL | D12: PRODUCCIÓN CAPSULA DE VIDEO | E12: 2280000 | F12: 1 | G12: 1 | H12: 1 | I12: 2280000 | J12: 0 | K12: 2280000
A13: BÉSAME | B13: DIGITAL | C13: DIGITAL | D13: REEL IG (PUBLICACIÓN) | E13: 1710000 | F13: 1 | G13: 1 | H13: 1 | I13: 1710000 | J13: 0.35 | K13: 1111500
A14: BÉSAME | B14: DIGITAL | C14: DIGITAL | D14: VIDEO TIK TOK (PUBLICACIÓN) | E14: 2462400 | F14: 1 | G14: 1 | H14: 1 | I14: 2462400 | J14: 0.32 | K14: 1666396
A15: BÉSAME | B15: DIGITAL | C15: MICROPROGRAMA | D15: PRODUCT PLACEMENT + INTERACCIÓN | E15: 5016000 | F15: 1 | G15: 1 | H15: 1 | I15: 5016000 | J15: 0.01 | K15: 4958824
A16: SALIDA CON VOCERO DE MARCA DE 4 A 5 MIN
A17: BÉSAME | B17: BOGOTÁ | C17: INEXPERTAS | D17: SALIDA CON VOCERO DE MARCA MORNING | E17: 7500000 | F17: 1 | G17: 1 | H17: 1 | I17: 7500000 | K17: 7500000
I18: 29746800 | K18: 22200250
A20: MICROPROGRAMA BÉSAME INEXPERTAS SIN VOCERO
A21: MARCA | B21: CIUDAD | C21: PRODUCTO | D21: VALORIZACION | E21: BRUTO | F21: VECES DIA | G21: No DIAS | H21: TOTAL | I21: VALOR BTO | J21: DTO | K21: VALOR NETO
A22: BÉSAME | B22: BOGOTÁ | C22: MICROPROGRAMA | D22: PRESENTACIÓN Y DESPEDIDA DEL MICROPROGRAMA | E22: 1139000 | F22: 1 | G22: 1 | H22: 1 | I22: 1139000 | J22: 0.75 | K22: 284750
A23: BÉSAME | B23: BOGOTÁ | C23: MICROPROGRAMA | D23: SECCIÓN ESPECIAL INEXPERTAS | E23: 2278000 | F23: 2 | G23: 1 | H23: 2 | I23: 4556000 | J23: 0.75 | K23: 1139000
A24: BÉSAME | B24: BOGOTÁ | C24: MICROPROGRAMA | D24: CUÑAS HASTA DE 20" MORNING | E24: 477000 | F24: 4 | G24: 1 | H24: 4 | I24: 1908000 | J24: 0.75 | K24: 477000
A25: BÉSAME | B25: BOGOTÁ | C25: MICROPROGRAMA | D25: CUÑA HASTA DE 20" MUSICAL | E25: 417000 | F25: 6 | G25: 1 | H25: 6 | I25: 2502000 | J25: 0.75 | K25: 625500
A26: BÉSAME | B26: BOGOTÁ | C26: MICROPROGRAMA | D26: PROMO 30'' PROGRAMACIÓN MUSICAL | E26: 278000 | F26: 10 | G26: 1 | H26: 10 | I26: 2780000 | J26: 0.75 | K26: 695000
A27: BÉSAME | B27: BOGOTÁ | C27: MICROPROGRAMA | D27: INDIVIDUALES PROGRAMACIÓN MUSICAL | E27: 779000 | F27: 4 | G27: 1 | H27: 4 | I27: 3116000 | J27: 0.75 | K27: 779000
A28: MICROPROGRAMA DETALLE DIGITAL (VIDEO SECCIÓN)
A29: BÉSAME | B29: BOGOTÁ | C29: MORNING | D29: SECCION ESPECIAL (RADIO) | E29: 3416400 | F29: 1 | G29: 1 | H29: 1 | I29: 3416400 | J29: 0.8 | K29: 683280
A30: BÉSAME | B30: DIGITAL | C30: DIGITAL | D30: PRODUCCIÓN CAPSULA DE VIDEO | E30: 2280000 | F30: 1 | G30: 1 | H30: 1 | I30: 2280000 | J30: 0 | K30: 2280000
A31: BÉSAME | B31: DIGITAL | C31: DIGITAL | D31: REEL IG (PUBLICACIÓN) | E31: 1710000 | F31: 1 | G31: 1 | H31: 1 | I31: 1710000 | J31: 0.35 | K31: 1111500
A32: BÉSAME | B32: DIGITAL | C32: DIGITAL | D32: VIDEO TIK TOK (PUBLICACIÓN) | E32: 2462400 | F32: 1 | G32: 1 | H32: 1 | I32: 2462400 | J32: 0.32 | K32: 1666396
A33: BÉSAME | B33: DIGITAL | C33: MICROPROGRAMA | D33: PRODUCT PLACEMENT + INTERACCIÓN | E33: 5016000 | F33: 1 | G33: 1 | H33: 1 | I33: 5016000 | J33: 0.01 | K33: 4958824
I34: 29746800 | K34: 14700250
A36: MICROPROGRAMA TROPICANA BOGOTÁ - SIN VOCERO
A37: MARCA | B37: CIUDAD | C37: PRODUCTO | D37: VALORIZACION | E37: BRUTO | F37: VECES DIA | G37: No DIAS | H37: TOTAL | I37: VALOR BTO | J37: DTO | K37: VALOR NETO
A38: TROPICANA | B38: BOGOTA | C38: MICROPROGRAMA | D38: PRESENTACIÓN Y DESPEDIDA DEL MICROPROGRAMA | E38: 2070000 | F38: 1 | G38: 1 | H38: 1 | I38: 2070000 | J38: 0.75 | K38: 517500
A39: TROPICANA | B39: BOGOTA | C39: MICROPROGRAMA | D39: SECCIÓN ESPECIAL COMO AMANECIO | E39: 4140000 | F39: 2 | G39: 1 | H39: 2 | I39: 8280000 | J39: 0.75 | K39: 2070000
A40: TROPICANA | B40: BOGOTA | C40: MICROPROGRAMA | D40: CUÑAS HASTA DE 20" MORNING | E40: 864000 | F40: 4 | G40: 1 | H40: 4 | I40: 3456000 | J40: 0.75 | K40: 864000
A41: TROPICANA | B41: BOGOTA | C41: MICROPROGRAMA | D41: CUÑA HASTA DE 20" MUSICAL | E41: 734250 | F41: 6 | G41: 1 | H41: 6 | I41: 4405500 | J41: 0.75 | K41: 1101375
A42: TROPICANA | B42: BOGOTA | C42: MICROPROGRAMA | D42: PROMO 30'' PROGRAMACIÓN MUSICAL | E42: 489500 | F42: 10 | G42: 1 | H42: 10 | I42: 4895000 | J42: 0.75 | K42: 1223750
A43: TROPICANA | B43: BOGOTA | C43: MICROPROGRAMA | D43: INDIVIDUALES PROGRAMACIÓN MUSICAL | E43: 1241000 | F43: 4 | G43: 1 | H43: 4 | I43: 4964000 | J43: 0.75 | K43: 1241000
...

Sheet Video Cubrimiento
B2: CARACOL - VIDEO CUBRIMIENTO BOGOTÁ
B3: MARCA | C3: CIUDAD | D3: PRODUCTO | E3: VALORIZACION | F3: VALOR VEZ | G3: VECES DIA | H3: No DIAS | I3: TOTAL | J3: VALOR BTO | K3: DTO | L3: VALOR NETO
B4: CARACOL | C4: DIGITAL | D4: DIGITAL | E4: PRODUCCIÓN CAPSULA DE VIDEO | F4: 12000000 | G4: 1 | H4: 1 | I4: =G4*H4 -> 1 | J4: =I4*F4 -> 12000000 | K4: 0.16558333 | L4: =J4-(J4*K4) -> 10013000
B5: CARACOL | C5: DIGITAL | D5: DIGITAL | E5: REEL IG (PUBLICACIÓN) | F5: 3990000 | G5: 1 | H5: 1 | I5: =G5*H5 -> 1 | J5: =I5*F5 -> 3990000 | K5: 0.35 | L5: =J5-(J5*K5) -> 2593500
B6: CARACOL | C6: DIGITAL | D6: DIGITAL | E6: REEL TIK TOK (PUBLICACIÓN) | F6: 3990000 | G6: 1 | H6: 1 | I6: =G6*H6 -> 1 | J6: =I6*F6 -> 3990000 | K6: 0.35 | L6: =J6-(J6*K6) -> 2593500
J7: =SUM(J4:J6) -> 19980000 | L7: =SUM(L4:L6) -> 15200000
B11: CARACOL - VIDEO CUBRIMIENTO LOCAL
B12: MARCA | C12: CIUDAD | D12: PRODUCTO | E12: VALORIZACION | F12: VALOR VEZ | G12: VECES DIA | H12: No DIAS | I12: TOTAL | J12: VALOR BTO | K12: DTO | L12: VALOR NETO
B13: CARACOL | C13: DIGITAL | D13: DIGITAL | E13: PRODUCCIÓN CAPSULA DE VIDEO | F13: 3000000 | G13: 1 | H13: 1 | I13: =G13*H13 -> 1 | J13: =I13*F13 -> 3000000 | K13: 0.25973333 | L13: =J13-(J13*K13) -> 2220800
B14: CARACOL | C14: DIGITAL | D14: DIGITAL | E14: REEL IG LOCAL | F14: 984000 | G14: 1 | H14: 1 | I14: =G14*H14 -> 1 | J14: =I14*F14 -> 984000 | K14: 0.35 | L14: =J14-(J14*K14) -> 639600
B15: CARACOL | C15: DIGITAL | D15: DIGITAL | E15: REEL TIKTOK LOCAL | F15: 984000 | G15: 1 | H15: 1 | I15: =G15*H15 -> 1 | J15: =I15*F15 -> 984000 | K15: 0.35 | L15: =J15-(J15*K15) -> 639600
J16: =SUM(J13:J15) -> 4968000 | L16: =SUM(L13:L15) -> 3500000
B20: TROPICANA - VIDEO CUBRIMIENTO LOCAL
B21: MARCA | C21: CIUDAD | D21: PRODUCTO | E21: VALORIZACION | F21: VALOR VEZ | G21: VECES DIA | H21: No DIAS | I21: TOTAL | J21: VALOR BTO | K21: DTO | L21: VALOR NETO
B22: TROPICANA | C22: DIGITAL | D22: DIGITAL | E22: PRODUCCIÓN CAPSULA DE VIDEO | F22: 2500000 | G22: 1 | H22: 1 | I22: =G22*H22 -> 1 | J22: =I22*F22 -> 2500000 | K22: 0.268 | L22: =J22-(J22*K22) -> 1830000
B23: TROPICANA | C23: DIGITAL | D23: DIGITAL | E23: REEL IG LOCAL | F23: 900000 | G23: 1 | H23: 1 | I23: =G23*H23 -> 1 | J23: =I23*F23 -> 900000 | K23: 0.35 | L23: =J23-(J23*K23) -> 585000
B24: TROPICANA | C24: DIGITAL | D24: DIGITAL | E24: REEL TIKTOK LOCAL | F24: 900000 | G24: 1 | H24: 1 | I24: =G24*H24 -> 1 | J24: =I24*F24 -> 900000 | K24: 0.35 | L24: =J24-(J24*K24) -> 585000
J25: =SUM(J22:J24) -> 4300000 | L25: =SUM(L22:L24) -> 3000000
B28: BÉSAME - VIDEO CUBRIMIENTO LOCAL
B29: MARCA | C29: CIUDAD | D29: PRODUCTO | E29: VALORIZACION | F29: VALOR VEZ | G29: VECES DIA | H29: No DIAS | I29: TOTAL | J29: VALOR BTO | K29: DTO | L29: VALOR NETO
B30: BÉSAME | C30: DIGITAL | D30: DIGITAL | E30: PRODUCCIÓN CAPSULA DE VIDEO | F30: 2500000 | G30: 1 | H30: 1 | I30: =G30*H30 -> 1 | J30: =I30*F30 -> 2500000 | K30: 0.268 | L30: =J30-(J30*K30) -> 1830000
B31: BÉSAME | C31: DIGITAL | D31: DIGITAL | E31: REEL IG LOCAL | F31: 900000 | G31: 1 | H31: 1 | I31: =G31*H31 -> 1 | J31: =I31*F31 -> 900000 | K31: 0.35 | L31: =J31-(J31*K31) -> 585000
